Workbook

Sheet Legenda & Referensi
A1: LEGENDA & REFERENSI PENULISAN
A2: Sumber tunggal untuk semua dropdown & lookup otomatis di seluruh form. JANGAN diubah urutannya.
A4: A. KODE BARANG (Level 1 — Gudang Utama)
A5: Kode Barang | B5: Nama Barang | C5: Kategori | D5: Satuan
A6: CT-001 | B6: Micro:bit V2 | C6: Controller | D6: pcs
A7: CT-002 | B7: Kabel Micro USB to Type C | C7: Controller | D7: pcs
A8: CT-003 | B8: Micro USB Cable Data Kabel | C8: Controller | D8: pcs
A9: OP-001 | B9: LED Merah | C9: Output Device | D9: pcs
A10: OP-002 | B10: LED Kuning | C10: Output Device | D10: pcs
A11: OP-003 | B11: LED Hijau | C11: Output Device | D11: pcs
A12: SN-001 | B12: Sensor Ultrasonik HC-SR04 | C12: Sensor | D12: pcs
A13: MT-001 | B13: Servo SG90 180° | C13: Motion | D13: pcs
A14: MT-002 | B14: Servo SG90 360° | C14: Motion | D14: pcs
A15: MT-003 | B15: Servo MG996R | C15: Motion | D15: pcs
A16: PW-001 | B16: Baterai AAA | C16: Power | D16: pcs
... A46: PC-006 | B46: Lembar Panduan | C46: Packaging | D46: lembar
A49: B. KODE MODUL
A50: Kode Modul | B50: Nama Modul
A51: M01 | B51: Controller Kit
A52: M02 | B52: LED Kit
A53: M03 | B53: Motion Kit
A54: M04 | B54: Sensor Kit
A55: M05 | B55: Power Kit
A56: M06 | B56: Mechanical Kit
A57: M07 | B57: Connection Kit
A58: M08 | B58: Jimu Trackbot
A59: M09 | B59: Erboblox
A60: M10 | B60: Sub-Assembly/Third-Party Kit
A61: M11 | B61: Sub-Assembly/Third-Party Kit
A62: M12
A63: M13
A66: C. KODE PROGRAM
A67: Kode Program | B67: Nama Program
A68: MB-BEG | B68: Microbit Beginner
A69: MB-ADV | B69: Microbit Advanced
A70: MB-RBT | B70: Robotik
A72: D. STATUS BARANG (Life Cycle)
A73: Status | B73: Arti
A74: RAW | B74: Baru diterima dari supplier
A75: READY | B75: Siap dipakai di Gudang Utama
...

Sheet List Komponen
A1: MICROBIT LEARNING KIT
A2: No | B2: Box / Kategori | C2: Modul | D2: Nama Komponen | E2: Jumlah | F2: Satuan | G2: Catatan
A3: 1 | B3: BOX 1 – Beginner Kit | C3: M01 - Controller Kit | D3: Micro:bit V2 | E3: 1 | F3: Pcs
A4: 2 | B4: BOX 1 – Beginner Kit | C4: M01 - Controller Kit | D4: Kabel Micro USB | E4: 1 | F4: Pcs
A5: 3 | B5: BOX 1 – Beginner Kit | C5: M01 - Controller Kit | D5: Kabel Micro Type-C | E5: 1 | F5: Pcs
A6: 4 | B6: BOX 1 – Beginner Kit | C6: M02 - LED Kit | D6: LED Merah | E6: 4 | F6: Pcs
A7: 5 | B7: BOX 1 – Beginner Kit | C7: M02 - LED Kit | D7: LED Hijau | E7: 4 | F7: Pcs
A8: 6 | B8: BOX 1 – Beginner Kit | C8: M02 - LED Kit | D8: LED Kuning | E8: 4 | F8: Pcs
A9: 7 | B9: BOX 1 – Beginner Kit | C9: M02 - LED Kit | D9: Resistor | E9: 12 | F9: Pcs
A10: 8 | B10: BOX 1 – Beginner Kit | C10: M07 - Connection Kit | D10: Breadboard Mini (170 TP) | E10: 1 | F10: Pcs
A11: 9 | B11: BOX 1 – Beginner Kit | C11: M07 - Connection Kit | D11: Blok Konektor | E11: 2 | F11: Pcs
A12: 10 | B12: BOX 1 – Beginner Kit | C12: M07 - Connection Kit | D12: Kabel Alligator | E12: 10 | F12: Pcs
A13: 11 | B13: BOX 1 – Beginner Kit | C13: M07 - Connection Kit | D13: Kabel Jumper Male to Male | E13: 20 | F13: Pcs
A14: 12 | B14: BOX 1 – Beginner Kit | C14: M07 - Connection Kit | D14: Kabel Jumper Male to Female | E14: 10 | F14: Pcs
... A24: 22 | B24: BOX 3 – Bricks | C24: M06 - Mechanical Kit | D24: Papan Lego / Base Plate | E24: 2 | F24: Pcs
D25: Total Item | E25: 95
A27: ROBOTIC EXPLORER
A28: No | B28: Box / Kategori | C28: Modul | D28: Nama Komponen | E28: Jumlah | F28: Satuan | G28: Catatan
A29: 1 | B29: BOX 1 – Beginner Kit | C29: M01 - Controller Kit | D29: Micro:bit V2 | E29: 1 | F29: Pcs
A30: 2 | B30: BOX 1 – Beginner Kit | C30: M01 - Controller Kit | D30: Kabel Micro USB | E30: 1 | F30: Pcs
A31: 3 | B31: BOX 1 – Beginner Kit | C31: M01 - Controller Kit | D31: Kabel Micro Type-C | E31: 1 | F31: Pcs
A32: 4 | B32: BOX 1 – Beginner Kit | C32: M02 - LED Kit | D32: LED Merah | E32: 4 | F32: Pcs
A33: 5 | B33: BOX 1 – Beginner Kit | C33: M02 - LED Kit | D33: LED Hijau | E33: 4 | F33: Pcs
A34: 6 | B34: BOX 1 – Beginner Kit | C34: M02 - LED Kit | D34: LED Kuning | E34: 4 | F34: Pcs
A35: 7 | B35: BOX 1 – Beginner Kit | C35: M02 - LED Kit | D35: Resistor | E35: 12 | F35: Pcs
A36: 8 | B36: BOX 1 – Beginner Kit | C36: M07 - Connection Kit | D36: Breadboard Mini (170 TP) | E36: 1 | F36: Pcs
A37: 9 | B37: BOX 1 – Beginner Kit | C37: M07 - Connection Kit | D37: Blok Konektor | E37: 2 | F37: Pcs
A38: 10 | B38: BOX 1 – Beginner Kit | C38: M07 - Connection Kit | D38: Kabel Alligator | E38: 10 | F38: Pcs
A39: 11 | B39: BOX 1 – Beginner Kit | C39: M07 - Connection Kit | D39: Kabel Jumper Male to Male | E39: 20 | F39: Pcs
A40: 12 | B40: BOX 1 – Beginner Kit | C40: M07 - Connection Kit | D40: Kabel Jumper Male to Female | E40: 10 | F40: Pcs
... A42: 14 | B42: Jimu Trackbot | C42: JM01 - Jimu | D42: Jimu Trackbot | E42: 1 | F42: Pcs
A44: Jimu Trackbot | B44: Finish Good
A45: Erboblox | B45: Finish Good
A46: Arduino Learning Kit | B46: Finish Good

Sheet Stock Akhir
A1: STOCK AKHIR — OTOMATIS DARI SEMUA FORM TRANSAKSI
A2: Semua kolom di sheet ini adalah FORMULA. Jangan ketik manual di sini — cukup isi form transaksi, angka di sini akan mengikuti sendiri.
A5: Kode Barang | B5: Nama Barang | C5: Kategori | D5: Satuan | E5: Total Diterima | F5: Dipakai di Produksi | G5: Kembali dari Repair (Berhasil) | H5: Disposed (Repair Gagal) | I5: Stock Gudang Utama (READY) | J5: Sedang Diproses (Modul/Box/Sekolah/Repair) | K5: Total Barang Aktif di Sistem | L5: Rusak Menunggu Repair
A6: ='Legenda & Referensi'!A6 -> CT-001 | B6: =IFERROR(VLOOKUP(A6,'Legenda & Referensi'!$A$6:$D$40,2,0),"") -> Micro:bit V2 | C6: =IFERROR(VLOOKUP(A6,'Legenda & Referensi'!$A$6:$D$40,3,0),"") -> Controller | D6: =IFERROR(VLOOKUP(A6,'Legenda & Referensi'!$A$6:$D$40,4,0),"") -> pcs | E6: =SUMIF('Penerimaan Barang'!$D:$D,A6,'Penerimaan Barang'!$F:$F) -> 0 | F6: =SUMIF('Form Produksi Modul'!$E:$E,A6,'Form Produksi Modul'!$G:$G) -> 0 | G6: =SUMIFS('Form Repair'!$H:$H,'Form Repair'!$C:$C,A6,'Form Repair'!$I:$I,"BERHASIL") -> 0 | H6: =SUMIFS('Form Repair'!$H:$H,'Form Repair'!$C:$C,A6,'Form Repair'!$I:$I,"GAGAL") -> 0 | I6: =E6-F6+G6 -> 0 | J6: =F6-G6-H6 -> 0 | K6: =I6+J6 -> 0 | L6: =SUMIF('Form Pengembalian'!$F:$F,A6,'Form Pengembalian'!$H:$H)-(G6+H6) -> 0
A7: ='Legenda & Referensi'!A7 -> CT-002 | B7: =IFERROR(VLOOKUP(A7,'Legenda & Referensi'!$A$6:$D$40,2,0),"") -> Kabel Micro USB to Type C | C7: =IFERROR(VLOOKUP(A7,'Legenda & Referensi'!$A$6:$D$40,3,0),"") -> Controller | D7: =IFERROR(VLOOKUP(A7,'Legenda & Referensi'!$A$6:$D$40,4,0),"") -> pcs | E7: =SUMIF('Penerimaan Barang'!$D:$D,A7,'Penerimaan Barang'!$F:$F) -> 0 | F7: =SUMIF('Form Produksi Modul'!$E:$E,A7,'Form Produksi Modul'!$G:$G) -> 0 | G7: =SUMIFS('Form Repair'!$H:$H,'Form Repair'!$C:$C,A7,'Form Repair'!$I:$I,"BERHASIL") -> 0 | H7: =SUMIFS('Form Repair'!$H:$H,'Form Repair'!$C:$C,A7,'Form Repair'!$I:$I,"GAGAL") -> 0 | I7: =E7-F7+G7 -> 0 | J7: =F7-G7-H7 -> 0 | K7: =I7+J7 -> 0 | L7: =SUMIF('Form Pengembalian'!$F:$F,A7,'Form Pengembalian'!$H:$H)-(G7+H7) -> 0
A8: ='Legenda & Referensi'!A8 -> CT-003 | B8: =IFERROR(VLOOKUP(A8,'Legenda & Referensi'!$A$6:$D$40,2,0),"") -> Micro USB Cable Data Kabel | C8: =IFERROR(VLOOKUP(A8,'Legenda & Referensi'!$A$6:$D$40,3,0),"") -> Controller | D8: =IFERROR(VLOOKUP(A8,'Legenda & Referensi'!$A$6:$D$40,4,0),"") -> pcs | E8: =SUMIF('Penerimaan Barang'!$D:$D,A8,'Penerimaan Barang'!$F:$F) -> 0 | F8: =SUMIF('Form Produksi Modul'!$E:$E,A8,'Form Produksi Modul'!$G:$G) -> 0 | G8: =SUMIFS('Form Repair'!$H:$H,'Form Repair'!$C:$C,A8,'Form Repair'!$I:$I,"BERHASIL") -> 0 | H8: =SUMIFS('Form Repair'!$H:$H,'Form Repair'!$C:$C,A8,'Form Repair'!$I:$I,"GAGAL") -> 0 | I8: =E8-F8+G8 -> 0 | J8: =F8-G8-H8 -> 0 | K8: =I8+J8 -> 0 | L8: =SUMIF('Form Pengembalian'!$F:$F,A8,'Form Pengembalian'!$H:$H)-(G8+H8) -> 0
A9: ='Legenda & Referensi'!A9 -> OP-001 | B9: =IFERROR(VLOOKUP(A9,'Legenda & Referensi'!$A$6:$D$40,2,0),"") -> LED Merah | C9: =IFERROR(VLOOKUP(A9,'Legenda & Referensi'!$A$6:$D$40,3,0),"") -> Output Device | D9: =IFERROR(VLOOKUP(A9,'Legenda & Referensi'!$A$6:$D$40,4,0),"") -> pcs | E9: =SUMIF('Penerimaan Barang'!$D:$D,A9,'Penerimaan Barang'!$F:$F) -> 0 | F9: =SUMIF('Form Produksi Modul'!$E:$E,A9,'Form Produksi Modul'!$G:$G) -> 0 | G9: =SUMIFS('Form Repair'!$H:$H,'Form Repair'!$C:$C,A9,'Form Repair'!$I:$I,"BERHASIL") -> 0 | H9: =SUMIFS('Form Repair'!$H:$H,'Form Repair'!$C:$C,A9,'Form Repair'!$I:$I,"GAGAL") -> 0 | I9: =E9-F9+G9 -> 0 | J9: =F9-G9-H9 -> 0 | K9: =I9+J9 -> 0 | L9: =SUMIF('Form Pengembalian'!$F:$F,A9,'Form Pengembalian'!$H:$H)-(G9+H9) -> 0
A10: ='Legenda & Referensi'!A10 -> OP-002 | B10: =IFERROR(VLOOKUP(A10,'Legenda & Referensi'!$A$6:$D$40,2,0),"") -> LED Kuning | C10: =IFERROR(VLOOKUP(A10,'Legenda & Referensi'!$A$6:$D$40,3,0),"") -> Output Device | D10: =IFERROR(VLOOKUP(A10,'Legenda & Referensi'!$A$6:$D$40,4,0),"") -> pcs | E10: =SUMIF('Penerimaan Barang'!$D:$D,A10,'Penerimaan Barang'!$F:$F) -> 0 | F10: =SUMIF('Form Produksi Modul'!$E:$E,A10,'Form Produksi Modul'!$G:$G) -> 0 | G10: =SUMIFS('Form Repair'!$H:$H,'Form Repair'!$C:$C,A10,'Form Repair'!$I:$I,"BERHASIL") -> 0 | H10: =SUMIFS('Form Repair'!$H:$H,'Form Repair'!$C:$C,A10,'Form Repair'!$I:$I,"GAGAL") -> 0 | I10: =E10-F10+G10 -> 0 | J10: =F10-G10-H10 -> 0 | K10: =I10+J10 -> 0 | L10: =SUMIF('Form Pengembalian'!$F:$F,A10,'Form Pengembalian'!$H:$H)-(G10+H10) -> 0
A11: ='Legenda & Referensi'!A11 -> OP-003 | B11: =IFERROR(VLOOKUP(A11,'Legenda & Referensi'!$A$6:$D$40,2,0),"") -> LED Hijau | C11: =IFERROR(VLOOKUP(A11,'Legenda & Referensi'!$A$6:$D$40,3,0),"") -> Output Device | D11: =IFERROR(VLOOKUP(A11,'Legenda & Referensi'!$A$6:$D$40,4,0),"") -> pcs | E11: =SUMIF('Penerimaan Barang'!$D:$D,A11,'Penerimaan Barang'!$F:$F) -> 0 | F11: =SUMIF('Form Produksi Modul'!$E:$E,A11,'Form Produksi Modul'!$G:$G) -> 0 | G11: =SUMIFS('Form Repair'!$H:$H,'Form Repair'!$C:$C,A11,'Form Repair'!$I:$I,"BERHASIL") -> 0 | H11: =SUMIFS('Form Repair'!$H:$H,'Form Repair'!$C:$C,A11,'Form Repair'!$I:$I,"GAGAL") -> 0 | I11: =E11-F11+G11 -> 0 | J11: =F11-G11-H11 -> 0 | K11: =I11+J11 -> 0 | L11: =SUMIF('Form Pengembalian'!$F:$F,A11,'Form Pengembalian'!$H:$H)-(G11+H11) -> 0
A12: ='Legenda & Referensi'!A12 -> SN-001 | B12: =IFERROR(VLOOKUP(A12,'Legenda & Referensi'!$A$6:$D$40,2,0),"") -> Sensor Ultrasonik HC-SR04 | C12: =IFERROR(VLOOKUP(A12,'Legenda & Referensi'!$A$6:$D$40,3,0),"") -> Sensor | D12: =IFERROR(VLOOKUP(A12,'Legenda & Referensi'!$A$6:$D$40,4,0),"") -> pcs | E12: =SUMIF('Penerimaan Barang'!$D:$D,A12,'Penerimaan Barang'!$F:$F) -> 0 | F12: =SUMIF('Form Produksi Modul'!$E:$E,A12,'Form Produksi Modul'!$G:$G) -> 0 | G12: =SUMIFS('Form Repair'!$H:$H,'Form Repair'!$C:$C,A12,'Form Repair'!$I:$I,"BERHASIL") -> 0 | H12: =SUMIFS('Form Repair'!$H:$H,'Form Repair'!$C:$C,A12,'Form Repair'!$I:$I,"GAGAL") -> 0 | I12: =E12-F12+G12 -> 0 | J12: =F12-G12-H12 -> 0 | K12: =I12+J12 -> 0 | L12: =SUMIF('Form Pengembalian'!$F:$F,A12,'Form Pengembalian'!$H:$H)-(G12+H12) -> 0
A13: ='Legenda & Referensi'!A13 -> MT-001 | B13: =IFERROR(VLOOKUP(A13,'Legenda & Referensi'!$A$6:$D$40,2,0),"") -> Servo SG90 180° | C13: =IFERROR(VLOOKUP(A13,'Legenda & Referensi'!$A$6:$D$40,3,0),"") -> Motion | D13: =IFERROR(VLOOKUP(A13,'Legenda & Referensi'!$A$6:$D$40,4,0),"") -> pcs | E13: =SUMIF('Penerimaan Barang'!$D:$D,A13,'Penerimaan Barang'!$F:$F) -> 0 | F13: =SUMIF('Form Produksi Modul'!$E:$E,A13,'Form Produksi Modul'!$G:$G) -> 0 | G13: =SUMIFS('Form Repair'!$H:$H,'Form Repair'!$C:$C,A13,'Form Repair'!$I:$I,"BERHASIL") -> 0 | H13: =SUMIFS('Form Repair'!$H:$H,'Form Repair'!$C:$C,A13,'Form Repair'!$I:$I,"GAGAL") -> 0 | I13: =E13-F13+G13 -> 0 | J13: =F13-G13-H13 -> 0 | K13: =I13+J13 -> 0 | L13: =SUMIF('Form Pengembalian'!$F:$F,A13,'Form Pengembalian'!$H:$H)-(G13+H13) -> 0
A14: ='Legenda & Referensi'!A14 -> MT-002 | B14: =IFERROR(VLOOKUP(A14,'Legenda & Referensi'!$A$6:$D$40,2,0),"") -> Servo SG90 360° | C14: =IFERROR(VLOOKUP(A14,'Legenda & Referensi'!$A$6:$D$40,3,0),"") -> Motion | D14: =IFERROR(VLOOKUP(A14,'Legenda & Referensi'!$A$6:$D$40,4,0),"") -> pcs | E14: =SUMIF('Penerimaan Barang'!$D:$D,A14,'Penerimaan Barang'!$F:$F) -> 0 | F14: =SUMIF('Form Produksi Modul'!$E:$E,A14,'Form Produksi Modul'!$G:$G) -> 0 | G14: =SUMIFS('Form Repair'!$H:$H,'Form Repair'!$C:$C,A14,'Form Repair'!$I:$I,"BERHASIL") -> 0 | H14: =SUMIFS('Form Repair'!$H:$H,'Form Repair'!$C:$C,A14,'Form Repair'!$I:$I,"GAGAL") -> 0 | I14: =E14-F14+G14 -> 0 | J14: =F14-G14-H14 -> 0 | K14: =I14+J14 -> 0 | L14: =SUMIF('Form Pengembalian'!$F:$F,A14,'Form Pengembalian'!$H:$H)-(G14+H14) -> 0
A15: ='Legenda & Referensi'!A15 -> MT-003 | B15: =IFERROR(VLOOKUP(A15,'Legenda & Referensi'!$A$6:$D$40,2,0),"") -> Servo MG996R | C15: =IFERROR(VLOOKUP(A15,'Legenda & Referensi'!$A$6:$D$40,3,0),"") -> Motion | D15: =IFERROR(VLOOKUP(A15,'Legenda & Referensi'!$A$6:$D$40,4,0),"") -> pcs | E15: =SUMIF('Penerimaan Barang'!$D:$D,A15,'Penerimaan Barang'!$F:$F) -> 0 | F15: =SUMIF('Form Produksi Modul'!$E:$E,A15,'Form Produksi Modul'!$G:$G) -> 0 | G15: =SUMIFS('Form Repair'!$H:$H,'Form Repair'!$C:$C,A15,'Form Repair'!$I:$I,"BERHASIL") -> 0 | H15: =SUMIFS('Form Repair'!$H:$H,'Form Repair'!$C:$C,A15,'Form Repair'!$I:$I,"GAGAL") -> 0 | I15: =E15-F15+G15 -> 0 | J15: =F15-G15-H15 -> 0 | K15: =I15+J15 -> 0 | L15: =SUMIF('Form Pengembalian'!$F:$F,A15,'Form Pengembalian'!$H:$H)-(G15+H15) -> 0
A16: ='Legenda & Referensi'!A16 -> PW-001 | B16: =IFERROR(VLOOKUP(A16,'Legenda & Referensi'!$A$6:$D$40,2,0),"") -> Baterai AAA | C16: =IFERROR(VLOOKUP(A16,'Legenda & Referensi'!$A$6:$D$40,3,0),"") -> Power | D16: =IFERROR(VLOOKUP(A16,'Legenda & Referensi'!$A$6:$D$40,4,0),"") -> pcs | E16: =SUMIF('Penerimaan Barang'!$D:$D,A16,'Penerimaan Barang'!$F:$F) -> 0 | F16: =SUMIF('Form Produksi Modul'!$E:$E,A16,'Form Produksi Modul'!$G:$G) -> 0 | G16: =SUMIFS('Form Repair'!$H:$H,'Form Repair'!$C:$C,A16,'Form Repair'!$I:$I,"BERHASIL") -> 0 | H16: =SUMIFS('Form Repair'!$H:$H,'Form Repair'!$C:$C,A16,'Form Repair'!$I:$I,"GAGAL") -> 0 | I16: =E16-F16+G16 -> 0 | J16: =F16-G16-H16 -> 0 | K16: =I16+J16 -> 0 | L16: =SUMIF('Form Pengembalian'!$F:$F,A16,'Form Pengembalian'!$H:$H)-(G16+H16) -> 0
A17: ='Legenda & Referensi'!A17 -> PW-002 | B17: =IFERROR(VLOOKUP(A17,'Legenda & Referensi'!$A$6:$D$40,2,0),"") -> Battery Holder 4xAAA | C17: =IFERROR(VLOOKUP(A17,'Legenda & Referensi'!$A$6:$D$40,3,0),"") -> Power | D17: =IFERROR(VLOOKUP(A17,'Legenda & Referensi'!$A$6:$D$40,4,0),"") -> pcs | E17: =SUMIF('Penerimaan Barang'!$D:$D,A17,'Penerimaan Barang'!$F:$F) -> 0 | F17: =SUMIF('Form Produksi Modul'!$E:$E,A17,'Form Produksi Modul'!$G:$G) -> 0 | G17: =SUMIFS('Form Repair'!$H:$H,'Form Repair'!$C:$C,A17,'Form Repair'!$I:$I,"BERHASIL") -> 0 | H17: =SUMIFS('Form Repair'!$H:$H,'Form Repair'!$C:$C,A17,'Form Repair'!$I:$I,"GAGAL") -> 0 | I17: =E17-F17+G17 -> 0 | J17: =F17-G17-H17 -> 0 | K17: =I17+J17 -> 0 | L17: =SUMIF('Form Pengembalian'!$F:$F,A17,'Form Pengembalian'!$H:$H)-(G17+H17) -> 0
... A40: ='Legenda & Referensi'!A40 -> TL-004 | B40: =IFERROR(VLOOKUP(A40,'Legenda & Referensi'!$A$6:$D$40,2,0),"") -> Lem Tembak | C40: =IFERROR(VLOOKUP(A40,'Legenda & Referensi'!$A$6:$D$40,3,0),"") -> Tools | D40: =IFERROR(VLOOKUP(A40,'Legenda & Referensi'!$A$6:$D$40,4,0),"") -> pcs | E40: =SUMIF('Penerimaan Barang'!$D:$D,A40,'Penerimaan Barang'!$F:$F) -> 0 | F40: =SUMIF('Form Produksi Modul'!$E:$E,A40,'Form Produksi Modul'!$G:$G) -> 0 | G40: =SUMIFS('Form Repair'!$H:$H,'Form Repair'!$C:$C,A40,'Form Repair'!$I:$I,"BERHASIL") -> 0 | H40: =SUMIFS('Form Repair'!$H:$H,'Form Repair'!$C:$C,A40,'Form Repair'!$I:$I,"GAGAL") -> 0 | I40: =E40-F40+G40 -> 0 | J40: =F40-G40-H40 -> 0 | K40: =I40+J40 -> 0 | L40: =SUMIF('Form Pengembalian'!$F:$F,A40,'Form Pengembalian'!$H:$H)-(G40+H40) -> 0
B41: TOTAL | E41: =SUM(E6:E40) -> 0 | F41: =SUM(F6:F40) -> 0 | G41: =SUM(G6:G40) -> 0 | H41: =SUM(H6:H40) -> 0 | I41: =SUM(I6:I40) -> 0 | J41: =SUM(J6:J40) -> 0 | K41: =SUM(K6:K40) -> 0 | L41: =SUM(L6:L40) -> 0

Sheet Penerimaan Barang
A1: FORM PENERIMAAN BARANG
A2: Kuning = isi tangan. Biru = otomatis (jangan diubah, formula sudah terpasang).
A3: Diisi oleh: Staf Gudang Utama
A5: No | B5: Tanggal | C5: No. PO (jika ada) | D5: Kode Barang | E5: Nama Barang | F5: Qty Diterima | G5: Satuan | H5: Kondisi Saat Diterima | I5: Diterima Oleh | J5: Catatan
B6: 46247 | C6: 1002 | D6: CN-007 | E6: =IFERROR(VLOOKUP(D6,'Legenda & Referensi'!$A$6:$D$46,2,0),"") -> Blok Konektor (CH-2 Push Connector) | G6: =IFERROR(VLOOKUP(D6,'Legenda & Referensi'!$A$6:$D$46,4,0),"") -> pcs
E7: =IFERROR(VLOOKUP(D7,'Legenda & Referensi'!$A$6:$D$46,2,0),"") | G7: =IFERROR(VLOOKUP(D7,'Legenda & Referensi'!$A$6:$D$46,4,0),"")
E8: =IFERROR(VLOOKUP(D8,'Legenda & Referensi'!$A$6:$D$46,2,0),"") | G8: =IFERROR(VLOOKUP(D8,'Legenda & Referensi'!$A$6:$D$46,4,0),"")
E9: =IFERROR(VLOOKUP(D9,'Legenda & Referensi'!$A$6:$D$46,2,0),"") | G9: =IFERROR(VLOOKUP(D9,'Legenda & Referensi'!$A$6:$D$46,4,0),"")
E10: =IFERROR(VLOOKUP(D10,'Legenda & Referensi'!$A$6:$D$46,2,0),"") | G10: =IFERROR(VLOOKUP(D10,'Legenda & Referensi'!$A$6:$D$46,4,0),"")
E11: =IFERROR(VLOOKUP(D11,'Legenda & Referensi'!$A$6:$D$46,2,0),"") | G11: =IFERROR(VLOOKUP(D11,'Legenda & Referensi'!$A$6:$D$46,4,0),"")
E12: =IFERROR(VLOOKUP(D12,'Legenda & Referensi'!$A$6:$D$46,2,0),"") | G12: =IFERROR(VLOOKUP(D12,'Legenda & Referensi'!$A$6:$D$46,4,0),"")
E13: =IFERROR(VLOOKUP(D13,'Legenda & Referensi'!$A$6:$D$46,2,0),"") | G13: =IFERROR(VLOOKUP(D13,'Legenda & Referensi'!$A$6:$D$46,4,0),"")
E14: =IFERROR(VLOOKUP(D14,'Legenda & Referensi'!$A$6:$D$46,2,0),"") | G14: =IFERROR(VLOOKUP(D14,'Legenda & Referensi'!$A$6:$D$46,4,0),"")
E15: =IFERROR(VLOOKUP(D15,'Legenda & Referensi'!$A$6:$D$46,2,0),"") | G15: =IFERROR(VLOOKUP(D15,'Legenda & Referensi'!$A$6:$D$46,4,0),"")
E16: =IFERROR(VLOOKUP(D16,'Legenda & Referensi'!$A$6:$D$46,2,0),"") | G16: =IFERROR(VLOOKUP(D16,'Legenda & Referensi'!$A$6:$D$46,4,0),"")
E17: =IFERROR(VLOOKUP(D17,'Legenda & Referensi'!$A$6:$D$46,2,0),"") | G17: =IFERROR(VLOOKUP(D17,'Legenda & Referensi'!$A$6:$D$46,4,0),"")
E18: =IFERROR(VLOOKUP(D18,'Legenda & Referensi'!$A$6:$D$46,2,0),"") | G18: =IFERROR(VLOOKUP(D18,'Legenda & Referensi'!$A$6:$D$46,4,0),"")
... E45: =IFERROR(VLOOKUP(D45,'Legenda & Referensi'!$A$6:$D$46,2,0),"") | G45: =IFERROR(VLOOKUP(D45,'Legenda & Referensi'!$A$6:$D$46,4,0),"")

Sheet Form Produksi Modul
A1: FORM PRODUKSI MODUL
A2: Kuning = isi tangan. Biru = otomatis (jangan diubah, formula sudah terpasang).
A3: Diisi oleh: Kepala Produksi / Staf Produksi
A5: No | B5: Tanggal | C5: Kode Modul | D5: Nama Modul | E5: Kode Barang Dipakai | F5: Nama Barang | G5: Qty Dipakai | H5: Jumlah Modul Dihasilkan | I5: Dirakit Oleh | J5: Catatan
C6: M01 | D6: =IFERROR(VLOOKUP(C6,'Legenda & Referensi'!$A$51:$B$58,2,0),"") -> Controller Kit | F6: =IFERROR(VLOOKUP(E6,'Legenda & Referensi'!$A$6:$D$40,2,0),"")
D7: =IFERROR(VLOOKUP(C7,'Legenda & Referensi'!$A$51:$B$58,2,0),"") | F7: =IFERROR(VLOOKUP(E7,'Legenda & Referensi'!$A$6:$D$40,2,0),"")
D8: =IFERROR(VLOOKUP(C8,'Legenda & Referensi'!$A$51:$B$58,2,0),"") | F8: =IFERROR(VLOOKUP(E8,'Legenda & Referensi'!$A$6:$D$40,2,0),"")
D9: =IFERROR(VLOOKUP(C9,'Legenda & Referensi'!$A$51:$B$58,2,0),"") | F9: =IFERROR(VLOOKUP(E9,'Legenda & Referensi'!$A$6:$D$40,2,0),"")
D10: =IFERROR(VLOOKUP(C10,'Legenda & Referensi'!$A$51:$B$58,2,0),"") | F10: =IFERROR(VLOOKUP(E10,'Legenda & Referensi'!$A$6:$D$40,2,0),"")
D11: =IFERROR(VLOOKUP(C11,'Legenda & Referensi'!$A$51:$B$58,2,0),"") | F11: =IFERROR(VLOOKUP(E11,'Legenda & Referensi'!$A$6:$D$40,2,0),"")
D12: =IFERROR(VLOOKUP(C12,'Legenda & Referensi'!$A$51:$B$58,2,0),"") | F12: =IFERROR(VLOOKUP(E12,'Legenda & Referensi'!$A$6:$D$40,2,0),"")
D13: =IFERROR(VLOOKUP(C13,'Legenda & Referensi'!$A$51:$B$58,2,0),"") | F13: =IFERROR(VLOOKUP(E13,'Legenda & Referensi'!$A$6:$D$40,2,0),"")
D14: =IFERROR(VLOOKUP(C14,'Legenda & Referensi'!$A$51:$B$58,2,0),"") | F14: =IFERROR(VLOOKUP(E14,'Legenda & Referensi'!$A$6:$D$40,2,0),"")
D15: =IFERROR(VLOOKUP(C15,'Legenda & Referensi'!$A$51:$B$58,2,0),"") | F15: =IFERROR(VLOOKUP(E15,'Legenda & Referensi'!$A$6:$D$40,2,0),"")
D16: =IFERROR(VLOOKUP(C16,'Legenda & Referensi'!$A$51:$B$58,2,0),"") | F16: =IFERROR(VLOOKUP(E16,'Legenda & Referensi'!$A$6:$D$40,2,0),"")
D17: =IFERROR(VLOOKUP(C17,'Legenda & Referensi'!$A$51:$B$58,2,0),"") | F17: =IFERROR(VLOOKUP(E17,'Legenda & Referensi'!$A$6:$D$40,2,0),"")
D18: =IFERROR(VLOOKUP(C18,'Legenda & Referensi'!$A$51:$B$58,2,0),"") | F18: =IFERROR(VLOOKUP(E18,'Legenda & Referensi'!$A$6:$D$40,2,0),"")
... D45: =IFERROR(VLOOKUP(C45,'Legenda & Referensi'!$A$51:$B$58,2,0),"") | F45: =IFERROR(VLOOKUP(E45,'Legenda & Referensi'!$A$6:$D$40,2,0),"")

Sheet Form QC Modul
A1: FORM QC MODUL
A2: Kuning = isi tangan. Biru = otomatis (jangan diubah, formula sudah terpasang).
A3: Diisi oleh: Kepala Produksi (pemeriksa kualitas)
A5: No | B5: Tanggal | C5: Kode Modul | D5: Nama Modul | E5: Kode Box Tujuan (jika ada) | F5: Hasil QC | G5: Item Bermasalah (jika Tidak Lolos) | H5: Diperiksa Oleh | I5: Catatan
D6: =IFERROR(VLOOKUP(C6,'Legenda & Referensi'!$A$51:$B$58,2,0),"")
D7: =IFERROR(VLOOKUP(C7,'Legenda & Referensi'!$A$51:$B$58,2,0),"")
D8: =IFERROR(VLOOKUP(C8,'Legenda & Referensi'!$A$51:$B$58,2,0),"")
D9: =IFERROR(VLOOKUP(C9,'Legenda & Referensi'!$A$51:$B$58,2,0),"")
D10: =IFERROR(VLOOKUP(C10,'Legenda & Referensi'!$A$51:$B$58,2,0),"")
D11: =IFERROR(VLOOKUP(C11,'Legenda & Referensi'!$A$51:$B$58,2,0),"")
D12: =IFERROR(VLOOKUP(C12,'Legenda & Referensi'!$A$51:$B$58,2,0),"")
D13: =IFERROR(VLOOKUP(C13,'Legenda & Referensi'!$A$51:$B$58,2,0),"")
D14: =IFERROR(VLOOKUP(C14,'Legenda & Referensi'!$A$51:$B$58,2,0),"")
D15: =IFERROR(VLOOKUP(C15,'Legenda & Referensi'!$A$51:$B$58,2,0),"")
D16: =IFERROR(VLOOKUP(C16,'Legenda & Referensi'!$A$51:$B$58,2,0),"")
D17: =IFERROR(VLOOKUP(C17,'Legenda & Referensi'!$A$51:$B$58,2,0),"")
... D45: =IFERROR(VLOOKUP(C45,'Legenda & Referensi'!$A$51:$B$58,2,0),"")

Sheet Form Pengiriman Sekolah
A1: FORM PENGIRIMAN SEKOLAH
A2: Kuning = isi tangan. Biru = otomatis (jangan diubah, formula sudah terpasang).
A3: Diisi oleh: Staf Gudang / Koordinator Sekolah
A5: No | B5: Tanggal Kirim | C5: Kode Box | D5: Kode Program | E5: Nama Program | F5: Nama Sekolah | G5: Jumlah Box Dikirim | H5: Dikirim Oleh | I5: Diterima Oleh (Sekolah) | J5: Catatan
E6: =IFERROR(VLOOKUP(D6,'Legenda & Referensi'!$A$68:$B$70,2,0),"")
E7: =IFERROR(VLOOKUP(D7,'Legenda & Referensi'!$A$68:$B$70,2,0),"")
E8: =IFERROR(VLOOKUP(D8,'Legenda & Referensi'!$A$68:$B$70,2,0),"")
E9: =IFERROR(VLOOKUP(D9,'Legenda & Referensi'!$A$68:$B$70,2,0),"")
E10: =IFERROR(VLOOKUP(D10,'Legenda & Referensi'!$A$68:$B$70,2,0),"")
E11: =IFERROR(VLOOKUP(D11,'Legenda & Referensi'!$A$68:$B$70,2,0),"")
E12: =IFERROR(VLOOKUP(D12,'Legenda & Referensi'!$A$68:$B$70,2,0),"")
E13: =IFERROR(VLOOKUP(D13,'Legenda & Referensi'!$A$68:$B$70,2,0),"")
E14: =IFERROR(VLOOKUP(D14,'Legenda & Referensi'!$A$68:$B$70,2,0),"")
E15: =IFERROR(VLOOKUP(D15,'Legenda & Referensi'!$A$68:$B$70,2,0),"")
E16: =IFERROR(VLOOKUP(D16,'Legenda & Referensi'!$A$68:$B$70,2,0),"")
E17: =IFERROR(VLOOKUP(D17,'Legenda & Referensi'!$A$68:$B$70,2,0),"")
... E45: =IFERROR(VLOOKUP(D45,'Legenda & Referensi'!$A$68:$B$70,2,0),"")

Sheet Form Pengembalian
A1: FORM PENGEMBALIAN
A2: Kuning = isi tangan. Biru = otomatis (jangan diubah, formula sudah terpasang).
A3: Diisi oleh: Staf Gudang (QC penerimaan kembali)
A5: No | B5: Tanggal Kembali | C5: Kode Box | D5: Nama Sekolah | E5: Kondisi | F5: Kode Barang Bermasalah | G5: Nama Barang | H5: Qty Bermasalah | I5: Diterima Oleh | J5: Catatan
G6: =IFERROR(VLOOKUP(F6,'Legenda & Referensi'!$A$6:$D$40,2,0),"")
G7: =IFERROR(VLOOKUP(F7,'Legenda & Referensi'!$A$6:$D$40,2,0),"")
G8: =IFERROR(VLOOKUP(F8,'Legenda & Referensi'!$A$6:$D$40,2,0),"")
G9: =IFERROR(VLOOKUP(F9,'Legenda & Referensi'!$A$6:$D$40,2,0),"")
G10: =IFERROR(VLOOKUP(F10,'Legenda & Referensi'!$A$6:$D$40,2,0),"")
G11: =IFERROR(VLOOKUP(F11,'Legenda & Referensi'!$A$6:$D$40,2,0),"")
G12: =IFERROR(VLOOKUP(F12,'Legenda & Referensi'!$A$6:$D$40,2,0),"")
G13: =IFERROR(VLOOKUP(F13,'Legenda & Referensi'!$A$6:$D$40,2,0),"")
G14: =IFERROR(VLOOKUP(F14,'Legenda & Referensi'!$A$6:$D$40,2,0),"")
G15: =IFERROR(VLOOKUP(F15,'Legenda & Referensi'!$A$6:$D$40,2,0),"")
G16: =IFERROR(VLOOKUP(F16,'Legenda & Referensi'!$A$6:$D$40,2,0),"")
G17: =IFERROR(VLOOKUP(F17,'Legenda & Referensi'!$A$6:$D$40,2,0),"")
... G45: =IFERROR(VLOOKUP(F45,'Legenda & Referensi'!$A$6:$D$40,2,0),"")

Sheet Form Repair
A1: FORM REPAIR
A2: Kuning = isi tangan. Biru = otomatis (jangan diubah, formula sudah terpasang).
A3: Diisi oleh: Teknisi Repair
A5: No | B5: Tanggal | C5: Kode Barang | D5: Nama Barang | E5: Asset ID (opsional) | F5: Jenis Kerusakan | G5: Tindakan Perbaikan | H5: Qty | I5: Hasil | J5: Diperbaiki Oleh | K5: Catatan
D6: =IFERROR(VLOOKUP(C6,'Legenda & Referensi'!$A$6:$D$40,2,0),"")
D7: =IFERROR(VLOOKUP(C7,'Legenda & Referensi'!$A$6:$D$40,2,0),"")
D8: =IFERROR(VLOOKUP(C8,'Legenda & Referensi'!$A$6:$D$40,2,0),"")
D9: =IFERROR(VLOOKUP(C9,'Legenda & Referensi'!$A$6:$D$40,2,0),"")
D10: =IFERROR(VLOOKUP(C10,'Legenda & Referensi'!$A$6:$D$40,2,0),"")
D11: =IFERROR(VLOOKUP(C11,'Legenda & Referensi'!$A$6:$D$40,2,0),"")
D12: =IFERROR(VLOOKUP(C12,'Legenda & Referensi'!$A$6:$D$40,2,0),"")
D13: =IFERROR(VLOOKUP(C13,'Legenda & Referensi'!$A$6:$D$40,2,0),"")
D14: =IFERROR(VLOOKUP(C14,'Legenda & Referensi'!$A$6:$D$40,2,0),"")
D15: =IFERROR(VLOOKUP(C15,'Legenda & Referensi'!$A$6:$D$40,2,0),"")
D16: =IFERROR(VLOOKUP(C16,'Legenda & Referensi'!$A$6:$D$40,2,0),"")
D17: =IFERROR(VLOOKUP(C17,'Legenda & Referensi'!$A$6:$D$40,2,0),"")
... D45: =IFERROR(VLOOKUP(C45,'Legenda & Referensi'!$A$6:$D$40,2,0),"")

Sheet Stock Opname
A1: FORM STOCK OPNAME
A2: Kuning = isi tangan. Biru = otomatis (jangan diubah, formula sudah terpasang).
A3: Diisi oleh: Staf Gudang bersama Kepala Produksi
A5: No | B5: Tanggal | C5: Kode Barang | D5: Nama Barang | E5: Qty Menurut Sistem | F5: Qty Hasil Hitung Fisik | G5: Selisih | H5: Keterangan Selisih | I5: Dihitung Oleh
D6: =IFERROR(VLOOKUP(C6,'Legenda & Referensi'!$A$6:$D$40,2,0),"") | E6: =IFERROR(VLOOKUP(C6,'Stock Akhir'!$A:$L,9,0),0) -> 0 | G6: =F6-E6 -> 0
D7: =IFERROR(VLOOKUP(C7,'Legenda & Referensi'!$A$6:$D$40,2,0),"") | E7: =IFERROR(VLOOKUP(C7,'Stock Akhir'!$A:$L,9,0),0) -> 0 | G7: =F7-E7 -> 0
D8: =IFERROR(VLOOKUP(C8,'Legenda & Referensi'!$A$6:$D$40,2,0),"") | E8: =IFERROR(VLOOKUP(C8,'Stock Akhir'!$A:$L,9,0),0) -> 0 | G8: =F8-E8 -> 0
D9: =IFERROR(VLOOKUP(C9,'Legenda & Referensi'!$A$6:$D$40,2,0),"") | E9: =IFERROR(VLOOKUP(C9,'Stock Akhir'!$A:$L,9,0),0) -> 0 | G9: =F9-E9 -> 0
D10: =IFERROR(VLOOKUP(C10,'Legenda & Referensi'!$A$6:$D$40,2,0),"") | E10: =IFERROR(VLOOKUP(C10,'Stock Akhir'!$A:$L,9,0),0) -> 0 | G10: =F10-E10 -> 0
D11: =IFERROR(VLOOKUP(C11,'Legenda & Referensi'!$A$6:$D$40,2,0),"") | E11: =IFERROR(VLOOKUP(C11,'Stock Akhir'!$A:$L,9,0),0) -> 0 | G11: =F11-E11 -> 0
D12: =IFERROR(VLOOKUP(C12,'Legenda & Referensi'!$A$6:$D$40,2,0),"") | E12: =IFERROR(VLOOKUP(C12,'Stock Akhir'!$A:$L,9,0),0) -> 0 | G12: =F12-E12 -> 0
D13: =IFERROR(VLOOKUP(C13,'Legenda & Referensi'!$A$6:$D$40,2,0),"") | E13: =IFERROR(VLOOKUP(C13,'Stock Akhir'!$A:$L,9,0),0) -> 0 | G13: =F13-E13 -> 0
D14: =IFERROR(VLOOKUP(C14,'Legenda & Referensi'!$A$6:$D$40,2,0),"") | E14: =IFERROR(VLOOKUP(C14,'Stock Akhir'!$A:$L,9,0),0) -> 0 | G14: =F14-E14 -> 0
D15: =IFERROR(VLOOKUP(C15,'Legenda & Referensi'!$A$6:$D$40,2,0),"") | E15: =IFERROR(VLOOKUP(C15,'Stock Akhir'!$A:$L,9,0),0) -> 0 | G15: =F15-E15 -> 0
D16: =IFERROR(VLOOKUP(C16,'Legenda & Referensi'!$A$6:$D$40,2,0),"") | E16: =IFERROR(VLOOKUP(C16,'Stock Akhir'!$A:$L,9,0),0) -> 0 | G16: =F16-E16 -> 0
D17: =IFERROR(VLOOKUP(C17,'Legenda & Referensi'!$A$6:$D$40,2,0),"") | E17: =IFERROR(VLOOKUP(C17,'Stock Akhir'!$A:$L,9,0),0) -> 0 | G17: =F17-E17 -> 0
... D45: =IFERROR(VLOOKUP(C45,'Legenda & Referensi'!$A$6:$D$40,2,0),"") | E45: =IFERROR(VLOOKUP(C45,'Stock Akhir'!$A:$L,9,0),0) -> 0 | G45: =F45-E45 -> 0
